<?xml version="1.0" ?>
<!-- =================================================================================== -->
<!-- |    This document was autogenerated by xacro from 3dof_example.urdf.xacro        | -->
<!-- |    EDITING THIS FILE BY HAND IS NOT RECOMMENDED                                 | -->
<!-- =================================================================================== -->
<robot name="3dof_example" xmlns:controller="http://playerstage.sourceforge.net/gazebo/xmlschema/#controller" xmlns:interface="http://playerstage.sourceforge.net/gazebo/xmlschema/#interface" xmlns:sensor="http://playerstage.sourceforge.net/gazebo/xmlschema/#sensor" xmlns:xacro="http://ros.org/wiki/xacro">
  <link name="base_link"/>
  <joint name="modul1_joint" type="revolute">
    <origin rpy="0 0 0" xyz="0 0 0.5"/>
    <parent link="base_link"/>
    <child link="modul1_link"/>
    <axis xyz="0 0 1"/>
    <limit effort="200" lower="-0.7854" upper="0.7854" velocity="0.6"/>
  </joint>
  <link name="modul1_link">
    <visual>
      <origin rpy="0 0 0" xyz="0 0 0"/>
      <geometry>
        <box size="0.1 0.02 0.5"/>
      </geometry>
    </visual>
    <collision>
      <origin rpy="0 0 0" xyz="0 0 0"/>
      <geometry>
        <box size="0.1 0.02 0.5"/>
      </geometry>
    </collision>
  </link>
  <joint name="modul2_joint" type="revolute">
    <origin rpy="0 0 0" xyz="0 0 0.5"/>
    <parent link="modul1_link"/>
    <child link="modul2_link"/>
    <axis xyz="0 0 1"/>
    <limit effort="200" lower="-0.7854" upper="0.7854" velocity="0.6"/>
  </joint>
  <link name="modul2_link">
    <visual>
      <origin rpy="0 0 0" xyz="0 0 0"/>
      <geometry>
        <box size="0.1 0.02 0.5"/>
      </geometry>
    </visual>
    <collision>
      <origin rpy="0 0 0" xyz="0 0 0"/>
      <geometry>
        <box size="0.1 0.02 0.5"/>
      </geometry>
    </collision>
  </link>
  <joint name="modul3_joint" type="revolute">
    <origin rpy="0 0 0" xyz="0 0 0.5"/>
    <parent link="modul2_link"/>
    <child link="modul3_link"/>
    <axis xyz="0 0 1"/>
    <limit effort="200" lower="-0.7854" upper="0.7854" velocity="0.6"/>
  </joint>
  <link name="modul3_link">
    <visual>
      <origin rpy="0 0 0" xyz="0 0 0"/>
      <geometry>
        <box size="0.1 0.02 0.5"/>
      </geometry>
    </visual>
    <collision>
      <origin rpy="0 0 0" xyz="0 0 0"/>
      <geometry>
        <box size="0.1 0.02 0.5"/>
      </geometry>
    </collision>
  </link>
</robot>

